Workbook
Name lstCategorias: OFFSET(Listas!$A$2,0,0,COUNTA(Listas!$A:$A)-1,1)
Name lstCategoriasGasto: OFFSET(Listas!$G$2,0,0,COUNTA(Listas!$G:$G)-1,1)
Name lstCategoriasIngreso: OFFSET(Listas!$I$2,0,0,COUNTA(Listas!$I:$I)-1,1)
Name lstClientes: OFFSET(Clientes!$A$2,0,0,COUNTA(Clientes!$A:$A)-1,1)
Name lstClientesNombres: OFFSET(Clientes!$B$2,0,0,COUNTA(Clientes!$B:$B)-1,1)
Name lstCuentas: OFFSET(Listas!$E$2,0,0,COUNTA(Listas!$E:$E)-1,1)
Name lstEstado: OFFSET(Listas!$K$2,0,0,COUNTA(Listas!$K:$K)-1,1)
Name lstMetodosPago: OFFSET(Listas!$C$2,0,0,COUNTA(Listas!$C:$C)-1,1)
Name lstProductos: OFFSET(Productos!$A$2,0,0,COUNTA(Productos!$A:$A)-1,1)
Name lstProveedores: OFFSET(Listas!$M$2,0,0,COUNTA(Listas!$M:$M)-1,1)

Sheet Guia
A1: GUIA RAPIDA
A3: 1) Carga y mantiene CLIENTES en la hoja Clientes.
A4: 2) Carga PRODUCTOS en la hoja Productos (precio venta, stock minimo).
A5: 3) Registra VENTAS en la hoja Ventas (usa los dropdowns).
A6: 4) Registra COMPRAS para actualizar stock.
A7: 5) Registra GASTOS e INGRESOS extra (no ventas) si aplica.
A8: 6) Mira Dashboard y Resumen. Todo se actualiza solo por formulas.

Sheet Dashboard
A1: DASHBOARD - TU TIENDA | B1: Columna1
A3: KPIs (Mes actual)
A4: Ventas | B4: =Resumen!A4 -> #REF!
A5: Ganancia Bruta | B5: =Resumen!C4 -> #REF!
A6: Gastos | B6: =Resumen!E4 -> 0
A7: Neto | B7: =Resumen!G4 -> #REF!

Sheet Ventas
A1: FECHA | B1: VENTA_ID | C1: CLIENTE_ID | D1: CLIENTE | E1: PRODUCTO | F1: CATEGORIA | G1: CANTIDAD | H1: PRECIO_MANUAL | I1: PRECIO_LISTA | J1: PRECIO_USADO | K1: TOTAL_VENTA | L1: COSTO_UNIT | M1: COSTO_TOTAL | N1: GANANCIA | O1: METODO_PAGO | P1: CUENTA | Q1: ESTADO | R1: NOTAS | S1: STOCK_DISP
A2: 46024 | B2: =IF(A2="","", "V"&TEXT(A2,"yymmdd")&"-"&TEXT(ROW()-1,"0000")) -> V260102-0001 | C2: =IF(D2="","",IFERROR(INDEX(tblClientes[ID],MATCH(D2,tblClientes[NOMBRE],0)),"")) -> C001 | D2: Flora Puga | E2: Voraz 20 KG | F2: =IF(E2="","",IFERROR(INDEX(tblProductos[CATEGORIA],MATCH(E2,tblProductos[ITEM],0)),"")) | G2: 1 | H2: 22580 | I2: =IF(E2="","",IFERROR(INDEX(tblProductos[PRECIO_VENTA],MATCH(E2,tblProductos[ITEM],0)),"")) | J2: =IF(H2="",I2,H2) -> 22580 | K2: =IF(G2="","",G2*J2) -> 22580 | L2: =IF(E2="","",IFERROR(INDEX(tblProductos[COSTO TOTAL],MATCH(E2,tblProductos[ITEM],0)),"")) | M2: =IF(G2="","",G2*L2) -> #VALUE! | N2: =IF(K2="","",K2-M2) -> #VALUE! | O2: EFECTIVO | P2: CAJA | Q2: PAGADO | S2: =IF(E2="","",IFERROR(INDEX(tblProductos[STOCK_ACTUAL],MATCH(E2,tblProductos[ITEM],0)),""))
A3: 46022 | B3: =IF(A3="","", "V"&TEXT(A3,"yymmdd")&"-"&TEXT(ROW()-1,"0000")) -> V251231-0002 | C3: C002 | E3: Avena instantanea | F3: =IF(E3="","",IFERROR(INDEX(tblProductos[CATEGORIA],MATCH(E3,tblProductos[ITEM],0)),"")) | G3: 3 | H3: 3330 | I3: =IF(E3="","",IFERROR(INDEX(tblProductos[PRECIO_VENTA],MATCH(E3,tblProductos[ITEM],0)),"")) | J3: =IF(H3="",I3,H3) -> 3330 | K3: =IF(G3="","",G3*J3) -> 9990 | L3: =IF(E3="","",IFERROR(INDEX(tblProductos[COSTO TOTAL],MATCH(E3,tblProductos[ITEM],0)),"")) | M3: =IF(G3="","",G3*L3) -> #VALUE! | N3: =IF(K3="","",K3-M3) -> #VALUE! | O3: EFECTIVO | P3: CAJA | Q3: PAGADO | S3: =IF(E3="","",IFERROR(INDEX(tblProductos[STOCK_ACTUAL],MATCH(E3,tblProductos[ITEM],0)),""))
A4: 46022 | B4: =IF(A4="","", "V"&TEXT(A4,"yymmdd")&"-"&TEXT(ROW()-1,"0000")) -> V251231-0003 | C4: =IF(D4="","",IFERROR(INDEX(tblClientes[ID],MATCH(D4,tblClientes[NOMBRE],0)),"")) | E4: Coco Vai | F4: =IF(E4="","",IFERROR(INDEX(tblProductos[CATEGORIA],MATCH(E4,tblProductos[ITEM],0)),"")) -> SAPHIRUS VARILLAS | G4: 1 | H4: 7200 | I4: =IF(E4="","",IFERROR(INDEX(tblProductos[PRECIO_VENTA],MATCH(E4,tblProductos[ITEM],0)),"")) -> 0 | J4: =IF(H4="",I4,H4) -> 7200 | K4: =IF(G4="","",G4*J4) -> 7200 | L4: =IF(E4="","",IFERROR(INDEX(tblProductos[COSTO TOTAL],MATCH(E4,tblProductos[ITEM],0)),"")) -> 3412.8 | M4: =IF(G4="","",G4*L4) -> 3412.8 | N4: =IF(K4="","",K4-M4) -> 3787.2 | O4: EFECTIVO | P4: CAJA | Q4: PAGADO | S4: =IF(E4="","",IFERROR(INDEX(tblProductos[STOCK_ACTUAL],MATCH(E4,tblProductos[ITEM],0)),"")) -> 0
B5: =IF(A5="","", "V"&TEXT(A5,"yymmdd")&"-"&TEXT(ROW()-1,"0000")) | C5: =IF(D5="","",IFERROR(INDEX(tblClientes[ID],MATCH(D5,tblClientes[NOMBRE],0)),"")) | F5: =IF(E5="","",IFERROR(INDEX(tblProductos[CATEGORIA],MATCH(E5,tblProductos[ITEM],0)),"")) | I5: =IF(E5="","",IFERROR(INDEX(tblProductos[PRECIO_VENTA],MATCH(E5,tblProductos[ITEM],0)),"")) | J5: =IF(H5="",I5,H5) | K5: =IF(G5="","",G5*J5) | L5: =IF(E5="","",IFERROR(INDEX(tblProductos[COSTO TOTAL],MATCH(E5,tblProductos[ITEM],0)),"")) | M5: =IF(G5="","",G5*L5) | N5: =IF(K5="","",K5-M5) | O5: EFECTIVO | P5: CAJA | Q5: PAGADO | S5: =IF(E5="","",IFERROR(INDEX(tblProductos[STOCK_ACTUAL],MATCH(E5,tblProductos[ITEM],0)),""))
B6: =IF(A6="","", "V"&TEXT(A6,"yymmdd")&"-"&TEXT(ROW()-1,"0000")) | C6: =IF(D6="","",IFERROR(INDEX(tblClientes[ID],MATCH(D6,tblClientes[NOMBRE],0)),"")) | F6: =IF(E6="","",IFERROR(INDEX(tblProductos[CATEGORIA],MATCH(E6,tblProductos[ITEM],0)),"")) | I6: =IF(E6="","",IFERROR(INDEX(tblProductos[PRECIO_VENTA],MATCH(E6,tblProductos[ITEM],0)),"")) | J6: =IF(H6="",I6,H6) | K6: =IF(G6="","",G6*J6) | L6: =IF(E6="","",IFERROR(INDEX(tblProductos[COSTO TOTAL],MATCH(E6,tblProductos[ITEM],0)),"")) | M6: =IF(G6="","",G6*L6) | N6: =IF(K6="","",K6-M6) | O6: EFECTIVO | P6: CAJA | Q6: PAGADO | S6: =IF(E6="","",IFERROR(INDEX(tblProductos[STOCK_ACTUAL],MATCH(E6,tblProductos[ITEM],0)),""))
B7: =IF(A7="","", "V"&TEXT(A7,"yymmdd")&"-"&TEXT(ROW()-1,"0000")) | C7: =IF(D7="","",IFERROR(INDEX(tblClientes[ID],MATCH(D7,tblClientes[NOMBRE],0)),"")) | F7: =IF(E7="","",IFERROR(INDEX(tblProductos[CATEGORIA],MATCH(E7,tblProductos[ITEM],0)),"")) | I7: =IF(E7="","",IFERROR(INDEX(tblProductos[PRECIO_VENTA],MATCH(E7,tblProductos[ITEM],0)),"")) | J7: =IF(H7="",I7,H7) | K7: =IF(G7="","",G7*J7) | L7: =IF(E7="","",IFERROR(INDEX(tblProductos[COSTO TOTAL],MATCH(E7,tblProductos[ITEM],0)),"")) | M7: =IF(G7="","",G7*L7) | N7: =IF(K7="","",K7-M7) | O7: EFECTIVO | P7: CAJA | Q7: PAGADO | S7: =IF(E7="","",IFERROR(INDEX(tblProductos[STOCK_ACTUAL],MATCH(E7,tblProductos[ITEM],0)),""))
B8: =IF(A8="","", "V"&TEXT(A8,"yymmdd")&"-"&TEXT(ROW()-1,"0000")) | C8: =IF(D8="","",IFERROR(INDEX(tblClientes[ID],MATCH(D8,tblClientes[NOMBRE],0)),"")) | F8: =IF(E8="","",IFERROR(INDEX(tblProductos[CATEGORIA],MATCH(E8,tblProductos[ITEM],0)),"")) | I8: =IF(E8="","",IFERROR(INDEX(tblProductos[PRECIO_VENTA],MATCH(E8,tblProductos[ITEM],0)),"")) | J8: =IF(H8="",I8,H8) | K8: =IF(G8="","",G8*J8) | L8: =IF(E8="","",IFERROR(INDEX(tblProductos[COSTO TOTAL],MATCH(E8,tblProductos[ITEM],0)),"")) | M8: =IF(G8="","",G8*L8) | N8: =IF(K8="","",K8-M8) | O8: EFECTIVO | P8: CAJA | Q8: PAGADO | S8: =IF(E8="","",IFERROR(INDEX(tblProductos[STOCK_ACTUAL],MATCH(E8,tblProductos[ITEM],0)),""))
B9: =IF(A9="","", "V"&TEXT(A9,"yymmdd")&"-"&TEXT(ROW()-1,"0000")) | C9: =IF(D9="","",IFERROR(INDEX(tblClientes[ID],MATCH(D9,tblClientes[NOMBRE],0)),"")) | F9: =IF(E9="","",IFERROR(INDEX(tblProductos[CATEGORIA],MATCH(E9,tblProductos[ITEM],0)),"")) | I9: =IF(E9="","",IFERROR(INDEX(tblProductos[PRECIO_VENTA],MATCH(E9,tblProductos[ITEM],0)),"")) | J9: =IF(H9="",I9,H9) | K9: =IF(G9="","",G9*J9) | L9: =IF(E9="","",IFERROR(INDEX(tblProductos[COSTO TOTAL],MATCH(E9,tblProductos[ITEM],0)),"")) | M9: =IF(G9="","",G9*L9) | N9: =IF(K9="","",K9-M9) | O9: EFECTIVO | P9: CAJA | Q9: PAGADO | S9: =IF(E9="","",IFERROR(INDEX(tblProductos[STOCK_ACTUAL],MATCH(E9,tblProductos[ITEM],0)),""))
B10: =IF(A10="","", "V"&TEXT(A10,"yymmdd")&"-"&TEXT(ROW()-1,"0000")) | C10: =IF(D10="","",IFERROR(INDEX(tblClientes[ID],MATCH(D10,tblClientes[NOMBRE],0)),"")) | F10: =IF(E10="","",IFERROR(INDEX(tblProductos[CATEGORIA],MATCH(E10,tblProductos[ITEM],0)),"")) | I10: =IF(E10="","",IFERROR(INDEX(tblProductos[PRECIO_VENTA],MATCH(E10,tblProductos[ITEM],0)),"")) | J10: =IF(H10="",I10,H10) | K10: =IF(G10="","",G10*J10) | L10: =IF(E10="","",IFERROR(INDEX(tblProductos[COSTO TOTAL],MATCH(E10,tblProductos[ITEM],0)),"")) | M10: =IF(G10="","",G10*L10) | N10: =IF(K10="","",K10-M10) | O10: EFECTIVO | P10: CAJA | Q10: PAGADO | S10: =IF(E10="","",IFERROR(INDEX(tblProductos[STOCK_ACTUAL],MATCH(E10,tblProductos[ITEM],0)),""))
B11: =IF(A11="","", "V"&TEXT(A11,"yymmdd")&"-"&TEXT(ROW()-1,"0000")) | C11: =IF(D11="","",IFERROR(INDEX(tblClientes[ID],MATCH(D11,tblClientes[NOMBRE],0)),"")) | F11: =IF(E11="","",IFERROR(INDEX(tblProductos[CATEGORIA],MATCH(E11,tblProductos[ITEM],0)),"")) | I11: =IF(E11="","",IFERROR(INDEX(tblProductos[PRECIO_VENTA],MATCH(E11,tblProductos[ITEM],0)),"")) | J11: =IF(H11="",I11,H11) | K11: =IF(G11="","",G11*J11) | L11: =IF(E11="","",IFERROR(INDEX(tblProductos[COSTO TOTAL],MATCH(E11,tblProductos[ITEM],0)),"")) | M11: =IF(G11="","",G11*L11) | N11: =IF(K11="","",K11-M11) | O11: EFECTIVO | P11: CAJA | Q11: PAGADO | S11: =IF(E11="","",IFERROR(INDEX(tblProductos[STOCK_ACTUAL],MATCH(E11,tblProductos[ITEM],0)),""))
B12: =IF(A12="","", "V"&TEXT(A12,"yymmdd")&"-"&TEXT(ROW()-1,"0000")) | C12: =IF(D12="","",IFERROR(INDEX(tblClientes[ID],MATCH(D12,tblClientes[NOMBRE],0)),"")) | F12: =IF(E12="","",IFERROR(INDEX(tblProductos[CATEGORIA],MATCH(E12,tblProductos[ITEM],0)),"")) | I12: =IF(E12="","",IFERROR(INDEX(tblProductos[PRECIO_VENTA],MATCH(E12,tblProductos[ITEM],0)),"")) | J12: =IF(H12="",I12,H12) | K12: =IF(G12="","",G12*J12) | L12: =IF(E12="","",IFERROR(INDEX(tblProductos[COSTO TOTAL],MATCH(E12,tblProductos[ITEM],0)),"")) | M12: =IF(G12="","",G12*L12) | N12: =IF(K12="","",K12-M12) | O12: EFECTIVO | P12: CAJA | Q12: PAGADO | S12: =IF(E12="","",IFERROR(INDEX(tblProductos[STOCK_ACTUAL],MATCH(E12,tblProductos[ITEM],0)),""))
B13: =IF(A13="","", "V"&TEXT(A13,"yymmdd")&"-"&TEXT(ROW()-1,"0000")) | C13: =IF(D13="","",IFERROR(INDEX(tblClientes[ID],MATCH(D13,tblClientes[NOMBRE],0)),"")) | F13: =IF(E13="","",IFERROR(INDEX(tblProductos[CATEGORIA],MATCH(E13,tblProductos[ITEM],0)),"")) | I13: =IF(E13="","",IFERROR(INDEX(tblProductos[PRECIO_VENTA],MATCH(E13,tblProductos[ITEM],0)),"")) | J13: =IF(H13="",I13,H13) | K13: =IF(G13="","",G13*J13) | L13: =IF(E13="","",IFERROR(INDEX(tblProductos[COSTO TOTAL],MATCH(E13,tblProductos[ITEM],0)),"")) | M13: =IF(G13="","",G13*L13) | N13: =IF(K13="","",K13-M13) | O13: EFECTIVO | P13: CAJA | Q13: PAGADO | S13: =IF(E13="","",IFERROR(INDEX(tblProductos[STOCK_ACTUAL],MATCH(E13,tblProductos[ITEM],0)),""))
B14: =IF(A14="","", "V"&TEXT(A14,"yymmdd")&"-"&TEXT(ROW()-1,"0000")) | C14: =IF(D14="","",IFERROR(INDEX(tblClientes[ID],MATCH(D14,tblClientes[NOMBRE],0)),"")) | F14: =IF(E14="","",IFERROR(INDEX(tblProductos[CATEGORIA],MATCH(E14,tblProductos[ITEM],0)),"")) | I14: =IF(E14="","",IFERROR(INDEX(tblProductos[PRECIO_VENTA],MATCH(E14,tblProductos[ITEM],0)),"")) | J14: =IF(H14="",I14,H14) | K14: =IF(G14="","",G14*J14) | L14: =IF(E14="","",IFERROR(INDEX(tblProductos[COSTO TOTAL],MATCH(E14,tblProductos[ITEM],0)),"")) | M14: =IF(G14="","",G14*L14) | N14: =IF(K14="","",K14-M14) | O14: EFECTIVO | P14: CAJA | Q14: PAGADO | S14: =IF(E14="","",IFERROR(INDEX(tblProductos[STOCK_ACTUAL],MATCH(E14,tblProductos[ITEM],0)),""))
B15: =IF(A15="","", "V"&TEXT(A15,"yymmdd")&"-"&TEXT(ROW()-1,"0000")) | C15: =IF(D15="","",IFERROR(INDEX(tblClientes[ID],MATCH(D15,tblClientes[NOMBRE],0)),"")) | F15: =IF(E15="","",IFERROR(INDEX(tblProductos[CATEGORIA],MATCH(E15,tblProductos[ITEM],0)),"")) | I15: =IF(E15="","",IFERROR(INDEX(tblProductos[PRECIO_VENTA],MATCH(E15,tblProductos[ITEM],0)),"")) | J15: =IF(H15="",I15,H15) | K15: =IF(G15="","",G15*J15) | L15: =IF(E15="","",IFERROR(INDEX(tblProductos[COSTO TOTAL],MATCH(E15,tblProductos[ITEM],0)),"")) | M15: =IF(G15="","",G15*L15) | N15: =IF(K15="","",K15-M15) | O15: EFECTIVO | P15: CAJA | Q15: PAGADO | S15: =IF(E15="","",IFERROR(INDEX(tblProductos[STOCK_ACTUAL],MATCH(E15,tblProductos[ITEM],0)),""))
B16: =IF(A16="","", "V"&TEXT(A16,"yymmdd")&"-"&TEXT(ROW()-1,"0000")) | C16: =IF(D16="","",IFERROR(INDEX(tblClientes[ID],MATCH(D16,tblClientes[NOMBRE],0)),"")) | F16: =IF(E16="","",IFERROR(INDEX(tblProductos[CATEGORIA],MATCH(E16,tblProductos[ITEM],0)),"")) | I16: =IF(E16="","",IFERROR(INDEX(tblProductos[PRECIO_VENTA],MATCH(E16,tblProductos[ITEM],0)),"")) | J16: =IF(H16="",I16,H16) | K16: =IF(G16="","",G16*J16) | L16: =IF(E16="","",IFERROR(INDEX(tblProductos[COSTO TOTAL],MATCH(E16,tblProductos[ITEM],0)),"")) | M16: =IF(G16="","",G16*L16) | N16: =IF(K16="","",K16-M16) | O16: EFECTIVO | P16: CAJA | Q16: PAGADO | S16: =IF(E16="","",IFERROR(INDEX(tblProductos[STOCK_ACTUAL],MATCH(E16,tblProductos[ITEM],0)),""))
... B501: =IF(A501="","", "V"&TEXT(A501,"yymmdd")&"-"&TEXT(ROW()-1,"0000")) | C501: =IF(D501="","",IFERROR(INDEX(tblClientes[ID],MATCH(D501,tblClientes[NOMBRE],0)),"")) | F501: =IF(E501="","",IFERROR(INDEX(tblProductos[CATEGORIA],MATCH(E501,tblProductos[ITEM],0)),"")) | I501: =IF(E501="","",IFERROR(INDEX(tblProductos[PRECIO_VENTA],MATCH(E501,tblProductos[ITEM],0)),"")) | J501: =IF(H501="",I501,H501) | K501: =IF(G501="","",G501*J501) | L501: =IF(E501="","",IFERROR(INDEX(tblProductos[COSTO TOTAL],MATCH(E501,tblProductos[ITEM],0)),"")) | M501: =IF(G501="","",G501*L501) | N501: =IF(K501="","",K501-M501) | O501: EFECTIVO | P501: CAJA | Q501: PAGADO | S501: =IF(E501="","",IFERROR(INDEX(tblProductos[STOCK_ACTUAL],MATCH(E501,tblProductos[ITEM],0)),""))

Sheet Compras
A1: FECHA | B1: COMPRA_ID | C1: PROVEEDOR | D1: PRODUCTO | E1: CATEGORIA | F1: CANTIDAD | G1: COSTO_UNIT | H1: TOTAL_COMPRA | I1: METODO_PAGO | J1: CUENTA | K1: NOTAS
B2: =IF(A2="","", "C"&TEXT(A2,"yymmdd")&"-"&TEXT(ROW()-1,"0000")) | E2: =IF(D2="","",IFERROR(INDEX(tblProductos[CATEGORIA],MATCH(D2,tblProductos[ITEM],0)),"")) | G2: =IF(D2="","",IFERROR(INDEX(tblProductos[COSTO TOTAL],MATCH(D2,tblProductos[ITEM],0)),"")) | H2: =IF(F2="","",F2*G2) | I2: TRANSFERENCIA | J2: BANCO
B3: =IF(A3="","", "C"&TEXT(A3,"yymmdd")&"-"&TEXT(ROW()-1,"0000")) | E3: =IF(D3="","",IFERROR(INDEX(tblProductos[CATEGORIA],MATCH(D3,tblProductos[ITEM],0)),"")) | G3: =IF(D3="","",IFERROR(INDEX(tblProductos[COSTO TOTAL],MATCH(D3,tblProductos[ITEM],0)),"")) | H3: =IF(F3="","",F3*G3) | I3: TRANSFERENCIA | J3: BANCO
B4: =IF(A4="","", "C"&TEXT(A4,"yymmdd")&"-"&TEXT(ROW()-1,"0000")) | E4: =IF(D4="","",IFERROR(INDEX(tblProductos[CATEGORIA],MATCH(D4,tblProductos[ITEM],0)),"")) | G4: =IF(D4="","",IFERROR(INDEX(tblProductos[COSTO TOTAL],MATCH(D4,tblProductos[ITEM],0)),"")) | H4: =IF(F4="","",F4*G4) | I4: TRANSFERENCIA | J4: BANCO
B5: =IF(A5="","", "C"&TEXT(A5,"yymmdd")&"-"&TEXT(ROW()-1,"0000")) | E5: =IF(D5="","",IFERROR(INDEX(tblProductos[CATEGORIA],MATCH(D5,tblProductos[ITEM],0)),"")) | G5: =IF(D5="","",IFERROR(INDEX(tblProductos[COSTO TOTAL],MATCH(D5,tblProductos[ITEM],0)),"")) | H5: =IF(F5="","",F5*G5) | I5: TRANSFERENCIA | J5: BANCO
B6: =IF(A6="","", "C"&TEXT(A6,"yymmdd")&"-"&TEXT(ROW()-1,"0000")) | E6: =IF(D6="","",IFERROR(INDEX(tblProductos[CATEGORIA],MATCH(D6,tblProductos[ITEM],0)),"")) | G6: =IF(D6="","",IFERROR(INDEX(tblProductos[COSTO TOTAL],MATCH(D6,tblProductos[ITEM],0)),"")) | H6: =IF(F6="","",F6*G6) | I6: TRANSFERENCIA | J6: BANCO
B7: =IF(A7="","", "C"&TEXT(A7,"yymmdd")&"-"&TEXT(ROW()-1,"0000")) | E7: =IF(D7="","",IFERROR(INDEX(tblProductos[CATEGORIA],MATCH(D7,tblProductos[ITEM],0)),"")) | G7: =IF(D7="","",IFERROR(INDEX(tblProductos[COSTO TOTAL],MATCH(D7,tblProductos[ITEM],0)),"")) | H7: =IF(F7="","",F7*G7) | I7: TRANSFERENCIA | J7: BANCO
B8: =IF(A8="","", "C"&TEXT(A8,"yymmdd")&"-"&TEXT(ROW()-1,"0000")) | E8: =IF(D8="","",IFERROR(INDEX(tblProductos[CATEGORIA],MATCH(D8,tblProductos[ITEM],0)),"")) | G8: =IF(D8="","",IFERROR(INDEX(tblProductos[COSTO TOTAL],MATCH(D8,tblProductos[ITEM],0)),"")) | H8: =IF(F8="","",F8*G8) | I8: TRANSFERENCIA | J8: BANCO
B9: =IF(A9="","", "C"&TEXT(A9,"yymmdd")&"-"&TEXT(ROW()-1,"0000")) | E9: =IF(D9="","",IFERROR(INDEX(tblProductos[CATEGORIA],MATCH(D9,tblProductos[ITEM],0)),"")) | G9: =IF(D9="","",IFERROR(INDEX(tblProductos[COSTO TOTAL],MATCH(D9,tblProductos[ITEM],0)),"")) | H9: =IF(F9="","",F9*G9) | I9: TRANSFERENCIA | J9: BANCO
B10: =IF(A10="","", "C"&TEXT(A10,"yymmdd")&"-"&TEXT(ROW()-1,"0000")) | E10: =IF(D10="","",IFERROR(INDEX(tblProductos[CATEGORIA],MATCH(D10,tblProductos[ITEM],0)),"")) | G10: =IF(D10="","",IFERROR(INDEX(tblProductos[COSTO TOTAL],MATCH(D10,tblProductos[ITEM],0)),"")) | H10: =IF(F10="","",F10*G10) | I10: TRANSFERENCIA | J10: BANCO
B11: =IF(A11="","", "C"&TEXT(A11,"yymmdd")&"-"&TEXT(ROW()-1,"0000")) | E11: =IF(D11="","",IFERROR(INDEX(tblProductos[CATEGORIA],MATCH(D11,tblProductos[ITEM],0)),"")) | G11: =IF(D11="","",IFERROR(INDEX(tblProductos[COSTO TOTAL],MATCH(D11,tblProductos[ITEM],0)),"")) | H11: =IF(F11="","",F11*G11) | I11: TRANSFERENCIA | J11: BANCO
B12: =IF(A12="","", "C"&TEXT(A12,"yymmdd")&"-"&TEXT(ROW()-1,"0000")) | E12: =IF(D12="","",IFERROR(INDEX(tblProductos[CATEGORIA],MATCH(D12,tblProductos[ITEM],0)),"")) | G12: =IF(D12="","",IFERROR(INDEX(tblProductos[COSTO TOTAL],MATCH(D12,tblProductos[ITEM],0)),"")) | H12: =IF(F12="","",F12*G12) | I12: TRANSFERENCIA | J12: BANCO
B13: =IF(A13="","", "C"&TEXT(A13,"yymmdd")&"-"&TEXT(ROW()-1,"0000")) | E13: =IF(D13="","",IFERROR(INDEX(tblProductos[CATEGORIA],MATCH(D13,tblProductos[ITEM],0)),"")) | G13: =IF(D13="","",IFERROR(INDEX(tblProductos[COSTO TOTAL],MATCH(D13,tblProductos[ITEM],0)),"")) | H13: =IF(F13="","",F13*G13) | I13: TRANSFERENCIA | J13: BANCO
... B401: =IF(A401="","", "C"&TEXT(A401,"yymmdd")&"-"&TEXT(ROW()-1,"0000")) | E401: =IF(D401="","",IFERROR(INDEX(tblProductos[CATEGORIA],MATCH(D401,tblProductos[ITEM],0)),"")) | G401: =IF(D401="","",IFERROR(INDEX(tblProductos[COSTO TOTAL],MATCH(D401,tblProductos[ITEM],0)),"")) | H401: =IF(F401="","",F401*G401) | I401: TRANSFERENCIA | J401: BANCO

Sheet Gastos
A1: FECHA | B1: GASTO_ID | C1: PROVEEDOR | D1: CATEGORIA_GASTO | E1: CONCEPTO | F1: MONTO | G1: METODO_PAGO | H1: CUENTA | I1: ESTADO | J1: NOTAS
A2: 46020 | B2: =IF(A2="","", "G"&TEXT(A2,"yymmdd")&"-"&TEXT(ROW()-1,"0000")) -> G251229-0001 | C2: SANCOR | D2: SEGURO | E2: SANCOR COOP SE0000030195186-020-000 006065 | F2: 68307.76 | G2: TARJETA | H2: BBVA | I2: PAGADO
B3: =IF(A3="","", "G"&TEXT(A3,"yymmdd")&"-"&TEXT(ROW()-1,"0000")) | G3: TRANSFERENCIA | H3: BANCO | I3: PAGADO
B4: =IF(A4="","", "G"&TEXT(A4,"yymmdd")&"-"&TEXT(ROW()-1,"0000")) | G4: TRANSFERENCIA | H4: BANCO | I4: PAGADO
B5: =IF(A5="","", "G"&TEXT(A5,"yymmdd")&"-"&TEXT(ROW()-1,"0000")) | G5: TRANSFERENCIA | H5: BANCO | I5: PAGADO
B6: =IF(A6="","", "G"&TEXT(A6,"yymmdd")&"-"&TEXT(ROW()-1,"0000")) | G6: TRANSFERENCIA | H6: BANCO | I6: PAGADO
B7: =IF(A7="","", "G"&TEXT(A7,"yymmdd")&"-"&TEXT(ROW()-1,"0000")) | G7: TRANSFERENCIA | H7: BANCO | I7: PAGADO
B8: =IF(A8="","", "G"&TEXT(A8,"yymmdd")&"-"&TEXT(ROW()-1,"0000")) | G8: TRANSFERENCIA | H8: BANCO | I8: PAGADO
B9: =IF(A9="","", "G"&TEXT(A9,"yymmdd")&"-"&TEXT(ROW()-1,"0000")) | G9: TRANSFERENCIA | H9: BANCO | I9: PAGADO
B10: =IF(A10="","", "G"&TEXT(A10,"yymmdd")&"-"&TEXT(ROW()-1,"0000")) | G10: TRANSFERENCIA | H10: BANCO | I10: PAGADO
B11: =IF(A11="","", "G"&TEXT(A11,"yymmdd")&"-"&TEXT(ROW()-1,"0000")) | G11: TRANSFERENCIA | H11: BANCO | I11: PAGADO
B12: =IF(A12="","", "G"&TEXT(A12,"yymmdd")&"-"&TEXT(ROW()-1,"0000")) | G12: TRANSFERENCIA | H12: BANCO | I12: PAGADO
B13: =IF(A13="","", "G"&TEXT(A13,"yymmdd")&"-"&TEXT(ROW()-1,"0000")) | G13: TRANSFERENCIA | H13: BANCO | I13: PAGADO
B14: =IF(A14="","", "G"&TEXT(A14,"yymmdd")&"-"&TEXT(ROW()-1,"0000")) | G14: TRANSFERENCIA | H14: BANCO | I14: PAGADO
... B380: =IF(A380="","", "G"&TEXT(A380,"yymmdd")&"-"&TEXT(ROW()-1,"0000")) | G380: TRANSFERENCIA | H380: BANCO | I380: PAGADO
G381: TRANSFERENCIA | H381: BANCO | I381: PAGADO
B382: =IF(A382="","", "G"&TEXT(A382,"yymmdd")&"-"&TEXT(ROW()-1,"0000")) | G382: TRANSFERENCIA | H382: BANCO | I382: PAGADO
B383: =IF(A383="","", "G"&TEXT(A383,"yymmdd")&"-"&TEXT(ROW()-1,"0000")) | G383: TRANSFERENCIA | H383: BANCO | I383: PAGADO
B384: =IF(A384="","", "G"&TEXT(A384,"yymmdd")&"-"&TEXT(ROW()-1,"0000")) | G384: TRANSFERENCIA | H384: BANCO | I384: PAGADO
B385: =IF(A385="","", "G"&TEXT(A385,"yymmdd")&"-"&TEXT(ROW()-1,"0000")) | G385: TRANSFERENCIA | H385: BANCO | I385: PAGADO
B386: =IF(A386="","", "G"&TEXT(A386,"yymmdd")&"-"&TEXT(ROW()-1,"0000")) | G386: TRANSFERENCIA | H386: BANCO | I386: PAGADO
B387: =IF(A387="","", "G"&TEXT(A387,"yymmdd")&"-"&TEXT(ROW()-1,"0000")) | G387: TRANSFERENCIA | H387: BANCO | I387: PAGADO
B388: =IF(A388="","", "G"&TEXT(A388,"yymmdd")&"-"&TEXT(ROW()-1,"0000")) | G388: TRANSFERENCIA | H388: BANCO | I388: PAGADO
B389: =IF(A389="","", "G"&TEXT(A389,"yymmdd")&"-"&TEXT(ROW()-1,"0000")) | G389: TRANSFERENCIA | H389: BANCO | I389: PAGADO
B390: =IF(A390="","", "G"&TEXT(A390,"yymmdd")&"-"&TEXT(ROW()-1,"0000")) | G390: TRANSFERENCIA | H390: BANCO | I390: PAGADO
B391: =IF(A391="","", "G"&TEXT(A391,"yymmdd")&"-"&TEXT(ROW()-1,"0000")) | G391: TRANSFERENCIA | H391: BANCO | I391: PAGADO
B392: =IF(A392="","", "G"&TEXT(A392,"yymmdd")&"-"&TEXT(ROW()-1,"0000")) | G392: TRANSFERENCIA | H392: BANCO | I392: PAGADO
B393: =IF(A393="","", "G"&TEXT(A393,"yymmdd")&"-"&TEXT(ROW()-1,"0000")) | G393: TRANSFERENCIA | H393: BANCO | I393: PAGADO
... B401: =IF(A401="","", "G"&TEXT(A401,"yymmdd")&"-"&TEXT(ROW()-1,"0000")) | G401: TRANSFERENCIA | H401: BANCO | I401: PAGADO

Sheet Ingresos
A1: FECHA | B1: INGRESO_ID | C1: FUENTE | D1: CATEGORIA_INGRESO | E1: CONCEPTO | F1: MONTO | G1: METODO_PAGO | H1: CUENTA | I1: ESTADO | J1: NOTAS
B2: =IF(A2="","", "I"&TEXT(A2,"yymmdd")&"-"&TEXT(ROW()-1,"0000")) | G2: EFECTIVO | H2: CAJA | I2: PAGADO
B3: =IF(A3="","", "I"&TEXT(A3,"yymmdd")&"-"&TEXT(ROW()-1,"0000")) | G3: EFECTIVO | H3: CAJA | I3: PAGADO
B4: =IF(A4="","", "I"&TEXT(A4,"yymmdd")&"-"&TEXT(ROW()-1,"0000")) | G4: EFECTIVO | H4: CAJA | I4: PAGADO
B5: =IF(A5="","", "I"&TEXT(A5,"yymmdd")&"-"&TEXT(ROW()-1,"0000")) | G5: EFECTIVO | H5: CAJA | I5: PAGADO
B6: =IF(A6="","", "I"&TEXT(A6,"yymmdd")&"-"&TEXT(ROW()-1,"0000")) | G6: EFECTIVO | H6: CAJA | I6: PAGADO
B7: =IF(A7="","", "I"&TEXT(A7,"yymmdd")&"-"&TEXT(ROW()-1,"0000")) | G7: EFECTIVO | H7: CAJA | I7: PAGADO
B8: =IF(A8="","", "I"&TEXT(A8,"yymmdd")&"-"&TEXT(ROW()-1,"0000")) | G8: EFECTIVO | H8: CAJA | I8: PAGADO
B9: =IF(A9="","", "I"&TEXT(A9,"yymmdd")&"-"&TEXT(ROW()-1,"0000")) | G9: EFECTIVO | H9: CAJA | I9: PAGADO
B10: =IF(A10="","", "I"&TEXT(A10,"yymmdd")&"-"&TEXT(ROW()-1,"0000")) | G10: EFECTIVO | H10: CAJA | I10: PAGADO
B11: =IF(A11="","", "I"&TEXT(A11,"yymmdd")&"-"&TEXT(ROW()-1,"0000")) | G11: EFECTIVO | H11: CAJA | I11: PAGADO
B12: =IF(A12="","", "I"&TEXT(A12,"yymmdd")&"-"&TEXT(ROW()-1,"0000")) | G12: EFECTIVO | H12: CAJA | I12: PAGADO
B13: =IF(A13="","", "I"&TEXT(A13,"yymmdd")&"-"&TEXT(ROW()-1,"0000")) | G13: EFECTIVO | H13: CAJA | I13: PAGADO
... B401: =IF(A401="","", "I"&TEXT(A401,"yymmdd")&"-"&TEXT(ROW()-1,"0000")) | G401: EFECTIVO | H401: CAJA | I401: PAGADO

Sheet Productos
A1: ITEM | B1: UNIDAD | C1: COSTO | D1: COSTO VINILO | E1: COSTO TOTAL | F1: CATEGORIA | G1: PRECIO_VENTA | H1: STOCK_MIN | I1: STOCK_ACTUAL | J1: VALOR_INV | K1: MARGEN_%
A2: SUPERHIT | B2: 90 | C2: 748.52767 | D2: 46.296296 | E2: =C2+D2 -> 794.82396 | F2: SATYA | H2: 0 | I2: =IF(A2="","",B2+IFERROR(SUMIFS(tblCompras[CANTIDAD],tblCompras[PRODUCTO],A2),0)-IFERROR(SUMIFS(#REF!,#REF!,A2),0)) -> 90 | J2: =IF(I2="","",I2*E2) -> 71534.157 | K2: =IF(G2="","",IFERROR((G2-E2)/G2,0))
A3: YOGA RITUAL | B3: 10 | C3: 998.44433 | D3: 46.296296 | E3: =C3+D3 -> 1044.7406 | F3: SATYA | H3: 0 | I3: =IF(A3="","",B3+IFERROR(SUMIFS(tblCompras[CANTIDAD],tblCompras[PRODUCTO],A3),0)-IFERROR(SUMIFS(#REF!,#REF!,A3),0)) -> 10 | J3: =IF(I3="","",I3*E3) -> 10447.406 | K3: =IF(G3="","",IFERROR((G3-E3)/G3,0))
A4: TUSCAN LEATHER | B4: 9 | C4: 998.44433 | D4: 46.296296 | E4: =C4+D4 -> 1044.7406 | F4: SATYA | H4: 0 | I4: =IF(A4="","",B4+IFERROR(SUMIFS(tblCompras[CANTIDAD],tblCompras[PRODUCTO],A4),0)-IFERROR(SUMIFS(#REF!,#REF!,A4),0)) -> 9 | J4: =IF(I4="","",I4*E4) -> 9402.6657 | K4: =IF(G4="","",IFERROR((G4-E4)/G4,0))
A5: TOBAK | B5: 8 | C5: 998.44433 | D5: 46.296296 | E5: =C5+D5 -> 1044.7406 | F5: SATYA | H5: 0 | I5: =IF(A5="","",B5+IFERROR(SUMIFS(tblCompras[CANTIDAD],tblCompras[PRODUCTO],A5),0)-IFERROR(SUMIFS(#REF!,#REF!,A5),0)) -> 8 | J5: =IF(I5="","",I5*E5) -> 8357.925 | K5: =IF(G5="","",IFERROR((G5-E5)/G5,0))
A6: SACRED SUTRA | B6: 9 | C6: 998.44433 | D6: 46.296296 | E6: =C6+D6 -> 1044.7406 | F6: SATYA | H6: 0 | I6: =IF(A6="","",B6+IFERROR(SUMIFS(tblCompras[CANTIDAD],tblCompras[PRODUCTO],A6),0)-IFERROR(SUMIFS(#REF!,#REF!,A6),0)) -> 9 | J6: =IF(I6="","",I6*E6) -> 9402.6657 | K6: =IF(G6="","",IFERROR((G6-E6)/G6,0))
A7: PURPLE BEAUTY | B7: 21 | C7: 998.44433 | D7: 46.296296 | E7: =C7+D7 -> 1044.7406 | F7: SATYA | H7: 0 | I7: =IF(A7="","",B7+IFERROR(SUMIFS(tblCompras[CANTIDAD],tblCompras[PRODUCTO],A7),0)-IFERROR(SUMIFS(#REF!,#REF!,A7),0)) -> 21 | J7: =IF(I7="","",I7*E7) -> 21939.553 | K7: =IF(G7="","",IFERROR((G7-E7)/G7,0))
A8: ARABIAN NIGHT | B8: 5 | C8: 998.44433 | D8: 46.296296 | E8: =C8+D8 -> 1044.7406 | F8: SATYA | H8: 0 | I8: =IF(A8="","",B8+IFERROR(SUMIFS(tblCompras[CANTIDAD],tblCompras[PRODUCTO],A8),0)-IFERROR(SUMIFS(#REF!,#REF!,A8),0)) -> 5 | J8: =IF(I8="","",I8*E8) -> 5223.7031 | K8: =IF(G8="","",IFERROR((G8-E8)/G8,0))
A9: DESI AROMA | B9: 10 | C9: 998.44433 | D9: 46.296296 | E9: =C9+D9 -> 1044.7406 | F9: SATYA | H9: 0 | I9: =IF(A9="","",B9+IFERROR(SUMIFS(tblCompras[CANTIDAD],tblCompras[PRODUCTO],A9),0)-IFERROR(SUMIFS(#REF!,#REF!,A9),0)) -> 10 | J9: =IF(I9="","",I9*E9) -> 10447.406 | K9: =IF(G9="","",IFERROR((G9-E9)/G9,0))
A10: ATHMA | B10: 2 | C10: 998.44433 | D10: 46.296296 | E10: =C10+D10 -> 1044.7406 | F10: SATYA | H10: 0 | I10: =IF(A10="","",B10+IFERROR(SUMIFS(tblCompras[CANTIDAD],tblCompras[PRODUCTO],A10),0)-IFERROR(SUMIFS(#REF!,#REF!,A10),0)) -> 2 | J10: =IF(I10="","",I10*E10) -> 2089.4813 | K10: =IF(G10="","",IFERROR((G10-E10)/G10,0))
A11: OMKAR | B11: 6 | C11: 998.44433 | D11: 46.296296 | E11: =C11+D11 -> 1044.7406 | F11: SATYA | H11: 0 | I11: =IF(A11="","",B11+IFERROR(SUMIFS(tblCompras[CANTIDAD],tblCompras[PRODUCTO],A11),0)-IFERROR(SUMIFS(#REF!,#REF!,A11),0)) -> 6 | J11: =IF(I11="","",I11*E11) -> 6268.4438 | K11: =IF(G11="","",IFERROR((G11-E11)/G11,0))
A12: DHARMA | B12: 11 | C12: 998.44433 | D12: 46.296296 | E12: =C12+D12 -> 1044.7406 | F12: SATYA | H12: 0 | I12: =IF(A12="","",B12+IFERROR(SUMIFS(tblCompras[CANTIDAD],tblCompras[PRODUCTO],A12),0)-IFERROR(SUMIFS(#REF!,#REF!,A12),0)) -> 11 | J12: =IF(I12="","",I12*E12) -> 11492.147 | K12: =IF(G12="","",IFERROR((G12-E12)/G12,0))
A13: MAGIC MONK | B13: 2 | C13: 998.44433 | D13: 46.296296 | E13: =C13+D13 -> 1044.7406 | F13: SATYA | H13: 0 | I13: =IF(A13="","",B13+IFERROR(SUMIFS(tblCompras[CANTIDAD],tblCompras[PRODUCTO],A13),0)-IFERROR(SUMIFS(#REF!,#REF!,A13),0)) -> 2 | J13: =IF(I13="","",I13*E13) -> 2089.4813 | K13: =IF(G13="","",IFERROR((G13-E13)/G13,0))
A14: BLUE BELL | B14: 0 | C14: 998.44433 | D14: 46.296296 | E14: =C14+D14 -> 1044.7406 | F14: SATYA | H14: 0 | I14: =IF(A14="","",B14+IFERROR(SUMIFS(tblCompras[CANTIDAD],tblCompras[PRODUCTO],A14),0)-IFERROR(SUMIFS(#REF!,#REF!,A14),0)) -> 0 | J14: =IF(I14="","",I14*E14) -> 0 | K14: =IF(G14="","",IFERROR((G14-E14)/G14,0))
A15: ESTAMPA ARP x15 | B15: 0 | C15: 0 | D15: 0 | E15: 29190 | F15: BALANCEADOS | H15: 0 | I15: =IF(A15="","",B15+IFERROR(SUMIFS(tblCompras[CANTIDAD],tblCompras[PRODUCTO],A15),0)-IFERROR(SUMIFS(#REF!,#REF!,A15),0)) -> 0 | J15: =IF(I15="","",I15*E15) -> 0 | K15: =IF(G15="","",IFERROR((G15-E15)/G15,0))
A16: ESTAMPA PLUS x20 | B16: 1 | C16: 0 | D16: 0 | E16: 35700 | F16: BALANCEADOS | H16: 0 | I16: =IF(A16="","",B16+IFERROR(SUMIFS(tblCompras[CANTIDAD],tblCompras[PRODUCTO],A16),0)-IFERROR(SUMIFS(#REF!,#REF!,A16),0)) -> 1 | J16: =IF(I16="","",I16*E16) -> 35700 | K16: =IF(G16="","",IFERROR((G16-E16)/G16,0))
A17: VAGONETA GOURMET x15 | B17: 0 | C17: 0 | D17: 0 | E17: 17370 | F17: BALANCEADOS | H17: 0 | I17: =IF(A17="","",B17+IFERROR(SUMIFS(tblCompras[CANTIDAD],tblCompras[PRODUCTO],A17),0)-IFERROR(SUMIFS(#REF!,#REF!,A17),0)) -> 0 | J17: =IF(I17="","",I17*E17) -> 0 | K17: =IF(G17="","",IFERROR((G17-E17)/G17,0))
A18: ESTAMPA CACHORRO x15 | B18: 0 | C18: 0 | D18: 0 | E18: 31620 | F18: BALANCEADOS | H18: 0 | I18: =IF(A18="","",B18+IFERROR(SUMIFS(tblCompras[CANTIDAD],tblCompras[PRODUCTO],A18),0)-IFERROR(SUMIFS(#REF!,#REF!,A18),0)) -> 0 | J18: =IF(I18="","",I18*E18) -> 0 | K18: =IF(G18="","",IFERROR((G18-E18)/G18,0))
A19: ESTAMPA CRIADORES x20 | B19: 0 | C19: 0 | D19: 0 | E19: 30080 | F19: BALANCEADOS | H19: 0 | I19: =IF(A19="","",B19+IFERROR(SUMIFS(tblCompras[CANTIDAD],tblCompras[PRODUCTO],A19),0)-IFERROR(SUMIFS(#REF!,#REF!,A19),0)) -> 0 | J19: =IF(I19="","",I19*E19) -> 0 | K19: =IF(G19="","",IFERROR((G19-E19)/G19,0))
A20: ESTAMPA PH CONTROL x1 | B20: 0 | C20: 0 | D20: 0 | E20: 2660 | F20: BALANCEADOS | H20: 0 | I20: =IF(A20="","",B20+IFERROR(SUMIFS(tblCompras[CANTIDAD],tblCompras[PRODUCTO],A20),0)-IFERROR(SUMIFS(#REF!,#REF!,A20),0)) -> 0 | J20: =IF(I20="","",I20*E20) -> 0 | K20: =IF(G20="","",IFERROR((G20-E20)/G20,0))
A21: PERROT x20 | B21: 0 | C21: 0 | D21: 0 | E21: 19690 | F21: BALANCEADOS | H21: 0 | I21: =IF(A21="","",B21+IFERROR(SUMIFS(tblCompras[CANTIDAD],tblCompras[PRODUCTO],A21),0)-IFERROR(SUMIFS(#REF!,#REF!,A21),0)) -> 0 | J21: =IF(I21="","",I21*E21) -> 0 | K21: =IF(G21="","",IFERROR((G21-E21)/G21,0))
A22: CANFEED ARP x3 | B22: 0 | C22: 0 | D22: 0 | E22: 9430 | F22: BALANCEADOS | H22: 0 | I22: =IF(A22="","",B22+IFERROR(SUMIFS(tblCompras[CANTIDAD],tblCompras[PRODUCTO],A22),0)-IFERROR(SUMIFS(#REF!,#REF!,A22),0)) -> 0 | J22: =IF(I22="","",I22*E22) -> 0 | K22: =IF(G22="","",IFERROR((G22-E22)/G22,0))
A23: CANFEED ARP x20 | B23: 0 | C23: 0 | D23: 0 | E23: 45440 | F23: BALANCEADOS | H23: 0 | I23: =IF(A23="","",B23+IFERROR(SUMIFS(tblCompras[CANTIDAD],tblCompras[PRODUCTO],A23),0)-IFERROR(SUMIFS(#REF!,#REF!,A23),0)) -> 0 | J23: =IF(I23="","",I23*E23) -> 0 | K23: =IF(G23="","",IFERROR((G23-E23)/G23,0))
A24: CANFEED LARGE x20 | B24: 0 | C24: 0 | D24: 0 | E24: 45440 | F24: BALANCEADOS | H24: 0 | I24: =IF(A24="","",B24+IFERROR(SUMIFS(tblCompras[CANTIDAD],tblCompras[PRODUCTO],A24),0)-IFERROR(SUMIFS(#REF!,#REF!,A24),0)) -> 0 | J24: =IF(I24="","",I24*E24) -> 0 | K24: =IF(G24="","",IFERROR((G24-E24)/G24,0))
A25: CANFEED CACHORRO L x15 | B25: 0 | C25: 0 | D25: 0 | E25: 41400 | F25: BALANCEADOS | H25: 0 | I25: =IF(A25="","",B25+IFERROR(SUMIFS(tblCompras[CANTIDAD],tblCompras[PRODUCTO],A25),0)-IFERROR(SUMIFS(#REF!,#REF!,A25),0)) -> 0 | J25: =IF(I25="","",I25*E25) -> 0 | K25: =IF(G25="","",IFERROR((G25-E25)/G25,0))
A26: CANFEED LIGHT x15 | B26: 0 | C26: 0 | D26: 0 | E26: 41110 | F26: BALANCEADOS | H26: 0 | I26: =IF(A26="","",B26+IFERROR(SUMIFS(tblCompras[CANTIDAD],tblCompras[PRODUCTO],A26),0)-IFERROR(SUMIFS(#REF!,#REF!,A26),0)) -> 0 | J26: =IF(I26="","",I26*E26) -> 0 | K26: =IF(G26="","",IFERROR((G26-E26)/G26,0))
... A36: PUPY CACHORRO x15 | B36: 1 | C36: 0 | D36: 0 | E36: 21410 | F36: BALANCEADOS | H36: 0 | I36: =IF(A36="","",B36+IFERROR(SUMIFS(tblCompras[CANTIDAD],tblCompras[PRODUCTO],A36),0)-IFERROR(SUMIFS(#REF!,#REF!,A36),0)) -> 1 | J36: =IF(I36="","",I36*E36) -> 21410 | K36: =IF(G36="","",IFERROR((G36-E36)/G36,0))
A37: SABROSITOS MIX x10 | B37: 1 | C37: 23600 | D37: 0 | E37: 23600 | F37: BALANCEADOS | G37: 31800 | H37: 0 | I37: =IF(A37="","",B37+IFERROR(SUMIFS(tblCompras[CANTIDAD],tblCompras[PRODUCTO],A37),0)-IFERROR(SUMIFS(#REF!,#REF!,A37),0)) -> 1 | J37: =IF(I37="","",I37*E37) -> 23600 | K37: =IF(G37="","",IFERROR((G37-E37)/G37,0)) -> 0.25786164
A38: EUKANUBA SENIOR +7 SMALL | B38: 0 | C38: 0 | D38: 0 | E38: 18540 | F38: BALANCEADOS | H38: 0 | I38: =IF(A38="","",B38+IFERROR(SUMIFS(tblCompras[CANTIDAD],tblCompras[PRODUCTO],A38),0)-IFERROR(SUMIFS(#REF!,#REF!,A38),0)) -> 0 | J38: =IF(I38="","",I38*E38) -> 0 | K38: =IF(G38="","",IFERROR((G38-E38)/G38,0))
A39: ROYAL MINI x3 | B39: 0 | C39: 0 | D39: 0 | E39: 30490 | F39: BALANCEADOS | H39: 0 | I39: =IF(A39="","",B39+IFERROR(SUMIFS(tblCompras[CANTIDAD],tblCompras[PRODUCTO],A39),0)-IFERROR(SUMIFS(#REF!,#REF!,A39),0)) -> 0 | J39: =IF(I39="","",I39*E39) -> 0 | K39: =IF(G39="","",IFERROR((G39-E39)/G39,0))
A40: SIEGER CRIADORES x20+2 | B40: 0 | C40: 0 | D40: 0 | E40: 71950 | F40: BALANCEADOS | H40: 0 | I40: =IF(A40="","",B40+IFERROR(SUMIFS(tblCompras[CANTIDAD],tblCompras[PRODUCTO],A40),0)-IFERROR(SUMIFS(#REF!,#REF!,A40),0)) -> 0 | J40: =IF(I40="","",I40*E40) -> 0 | K40: =IF(G40="","",IFERROR((G40-E40)/G40,0))
A41: AGILITY CAT x1.5 | B41: 0 | C41: 0 | D41: 0 | E41: 9780 | F41: BALANCEADOS | H41: 0 | I41: =IF(A41="","",B41+IFERROR(SUMIFS(tblCompras[CANTIDAD],tblCompras[PRODUCTO],A41),0)-IFERROR(SUMIFS(#REF!,#REF!,A41),0)) -> 0 | J41: =IF(I41="","",I41*E41) -> 0 | K41: =IF(G41="","",IFERROR((G41-E41)/G41,0))
A42: AGILITY CAT x10 | B42: 0 | C42: 0 | D42: 0 | E42: 49450 | F42: BALANCEADOS | H42: 0 | I42: =IF(A42="","",B42+IFERROR(SUMIFS(tblCompras[CANTIDAD],tblCompras[PRODUCTO],A42),0)-IFERROR(SUMIFS(#REF!,#REF!,A42),0)) -> 0 | J42: =IF(I42="","",I42*E42) -> 0 | K42: =IF(G42="","",IFERROR((G42-E42)/G42,0))
A43: AGILITY URINARY x1.5 | B43: 0 | C43: 0 | D43: 0 | E43: 10600 | F43: BALANCEADOS | H43: 0 | I43: =IF(A43="","",B43+IFERROR(SUMIFS(tblCompras[CANTIDAD],tblCompras[PRODUCTO],A43),0)-IFERROR(SUMIFS(#REF!,#REF!,A43),0)) -> 0 | J43: =IF(I43="","",I43*E43) -> 0 | K43: =IF(G43="","",IFERROR((G43-E43)/G43,0))
A44: AGILITY URINARY x10 | B44: 0 | C44: 0 | D44: 0 | E44: 53510 | F44: BALANCEADOS | H44: 0 | I44: =IF(A44="","",B44+IFERROR(SUMIFS(tblCompras[CANTIDAD],tblCompras[PRODUCTO],A44),0)-IFERROR(SUMIFS(#REF!,#REF!,A44),0)) -> 0 | J44: =IF(I44="","",I44*E44) -> 0 | K44: =IF(G44="","",IFERROR((G44-E44)/G44,0))
A45: 7 VIDAS x10 (NARANJA) | B45: 1 | C45: 0 | D45: 0 | E45: 38060 | F45: BALANCEADOS | H45: 0 | I45: =IF(A45="","",B45+IFERROR(SUMIFS(tblCompras[CANTIDAD],tblCompras[PRODUCTO],A45),0)-IFERROR(SUMIFS(#REF!,#REF!,A45),0)) -> 1 | J45: =IF(I45="","",I45*E45) -> 38060 | K45: =IF(G45="","",IFERROR((G45-E45)/G45,0))
A46: EXCELLENT MAINTENANCE x20 | B46: 0 | C46: 0 | D46: 0 | E46: 56052.25 | F46: BALANCEADOS | H46: 0 | I46: =IF(A46="","",B46+IFERROR(SUMIFS(tblCompras[CANTIDAD],tblCompras[PRODUCTO],A46),0)-IFERROR(SUMIFS(#REF!,#REF!,A46),0)) -> 0 | J46: =IF(I46="","",I46*E46) -> 0 | K46: =IF(G46="","",IFERROR((G46-E46)/G46,0))
A47: LIMPCAT PIEDRA AGLUTINANTE x2 KG | B47: 2 | C47: 0 | D47: 0 | E47: 1400 | F47: BALANCEADOS | H47: 0 | I47: =IF(A47="","",B47+IFERROR(SUMIFS(tblCompras[CANTIDAD],tblCompras[PRODUCTO],A47),0)-IFERROR(SUMIFS(#REF!,#REF!,A47),0)) -> 2 | J47: =IF(I47="","",I47*E47) -> 2800 | K47: =IF(G47="","",IFERROR((G47-E47)/G47,0))
A48: DIABSORB x8dm3 | B48: 4 | C48: 0 | D48: 0 | E48: 1680 | F48: BALANCEADOS | H48: 0 | I48: =IF(A48="","",B48+IFERROR(SUMIFS(tblCompras[CANTIDAD],tblCompras[PRODUCTO],A48),0)-IFERROR(SUMIFS(#REF!,#REF!,A48),0)) -> 4 | J48: =IF(I48="","",I48*E48) -> 6720 | K48: =IF(G48="","",IFERROR((G48-E48)/G48,0))
A49: DIABSORB x25 | B49: 0 | C49: 0 | D49: 0 | E49: 7560 | F49: BALANCEADOS | H49: 0 | I49: =IF(A49="","",B49+IFERROR(SUMIFS(tblCompras[CANTIDAD],tblCompras[PRODUCTO],A49),0)-IFERROR(SUMIFS(#REF!,#REF!,A49),0)) -> 0 | J49: =IF(I49="","",I49*E49) -> 0 | K49: =IF(G49="","",IFERROR((G49-E49)/G49,0))
...

Sheet Clientes
A1: ID | B1: NOMBRE | C1: CELU | D1: UBICACIÓN | E1: EMAIL | F1: NOTAS | G1: ACTIVO
A2: C001 | B2: Flora Puga | C2: +54 9 11 4940-4045 | D2: Villantonio A-05 | G2: SI
A3: C002 | B3: Lili Hostel Casa Blanca | C3: +54 9 2664 48-7887 | D3: https://maps.app.goo.gl/e7FwHjaRPHLXCEA86 | G3: SI
A4: C003 | B4: Frankus Cruz de P | C4: +54 9 2664 61-6192 | G4: SI
A5: C004
A6: C005
A7: C006
A8: C007
A9: C008
A10: C009
A11: C010
A12: C011
A13: C012
A14: C013
A15: C014
A16: C015
... A598: C597

Sheet Resumen
A1: RESUMEN FINANCIERO
A3: Ventas (Mes) | C3: Ganancia Bruta (Mes) | E3: Gastos (Mes) | G3: Neto (Mes)
A4: =SUMIFS(#REF!,#REF!,">="&EOMONTH(TODAY(),-1)+1,#REF!,"<"&EOMONTH(TODAY(),0)+1,#REF!,"PAGADO") -> #REF! | C4: =SUMIFS(#REF!,#REF!,">="&EOMONTH(TODAY(),-1)+1,#REF!,"<"&EOMONTH(TODAY(),0)+1,#REF!,"PAGADO") -> #REF! | E4: =SUMIFS(tblGastos[MONTO],tblGastos[FECHA],">="&EOMONTH(TODAY(),-1)+1,tblGastos[FECHA],"<"&EOMONTH(TODAY(),0)+1,tblGastos[ESTADO],"PAGADO") -> 0 | G4: =A4+C4-E4+SUMIFS(tblIngresos[MONTO],tblIngresos[FECHA],">="&EOMONTH(TODAY(),-1)+1,tblIngresos[FECHA],"<"&EOMONTH(TODAY(),0)+1,tblIngresos[ESTADO],"PAGADO") -> #REF!
A6: MES | B6: VENTAS | C6: COSTO | D6: GANANCIA_BRUTA | E6: GASTOS | F6: OTROS_INGRESOS | G6: GANANCIA_NETA | H6: RANGO 12M
A7: =EOMONTH(TODAY(),-11)+1 -> 45717 | B7: =SUMIFS(#REF!,#REF!,">="&$A7,#REF!,"<"&EDATE($A7,1),#REF!,"PAGADO") -> #REF! | C7: =SUMIFS(#REF!,#REF!,">="&$A7,#REF!,"<"&EDATE($A7,1),#REF!,"PAGADO") -> #REF! | D7: =B7-C7 -> #REF! | E7: =SUMIFS(tblGastos[MONTO],tblGastos[FECHA],">="&$A7,tblGastos[FECHA],"<"&EDATE($A7,1),tblGastos[ESTADO],"PAGADO") -> 0 | F7: =SUMIFS(tblIngresos[MONTO],tblIngresos[FECHA],">="&$A7,tblIngresos[FECHA],"<"&EDATE($A7,1),tblIngresos[ESTADO],"PAGADO") -> 0 | G7: =D7-E7+F7 -> #REF! | H7: =A7 -> 45717 | I7: Inicio
A8: =EOMONTH(TODAY(),-10)+1 -> 45748 | B8: =SUMIFS(#REF!,#REF!,">="&$A8,#REF!,"<"&EDATE($A8,1),#REF!,"PAGADO") -> #REF! | C8: =SUMIFS(#REF!,#REF!,">="&$A8,#REF!,"<"&EDATE($A8,1),#REF!,"PAGADO") -> #REF! | D8: =B8-C8 -> #REF! | E8: =SUMIFS(tblGastos[MONTO],tblGastos[FECHA],">="&$A8,tblGastos[FECHA],"<"&EDATE($A8,1),tblGastos[ESTADO],"PAGADO") -> 0 | F8: =SUMIFS(tblIngresos[MONTO],tblIngresos[FECHA],">="&$A8,tblIngresos[FECHA],"<"&EDATE($A8,1),tblIngresos[ESTADO],"PAGADO") -> 0 | G8: =D8-E8+F8 -> #REF! | H8: =EDATE(A18,1) -> 46082 | I8: Fin
A9: =EOMONTH(TODAY(),-9)+1 -> 45778 | B9: =SUMIFS(#REF!,#REF!,">="&$A9,#REF!,"<"&EDATE($A9,1),#REF!,"PAGADO") -> #REF! | C9: =SUMIFS(#REF!,#REF!,">="&$A9,#REF!,"<"&EDATE($A9,1),#REF!,"PAGADO") -> #REF! | D9: =B9-C9 -> #REF! | E9: =SUMIFS(tblGastos[MONTO],tblGastos[FECHA],">="&$A9,tblGastos[FECHA],"<"&EDATE($A9,1),tblGastos[ESTADO],"PAGADO") -> 0 | F9: =SUMIFS(tblIngresos[MONTO],tblIngresos[FECHA],">="&$A9,tblIngresos[FECHA],"<"&EDATE($A9,1),tblIngresos[ESTADO],"PAGADO") -> 0 | G9: =D9-E9+F9 -> #REF!
A10: =EOMONTH(TODAY(),-8)+1 -> 45809 | B10: =SUMIFS(#REF!,#REF!,">="&$A10,#REF!,"<"&EDATE($A10,1),#REF!,"PAGADO") -> #REF! | C10: =SUMIFS(#REF!,#REF!,">="&$A10,#REF!,"<"&EDATE($A10,1),#REF!,"PAGADO") -> #REF! | D10: =B10-C10 -> #REF! | E10: =SUMIFS(tblGastos[MONTO],tblGastos[FECHA],">="&$A10,tblGastos[FECHA],"<"&EDATE($A10,1),tblGastos[ESTADO],"PAGADO") -> 0 | F10: =SUMIFS(tblIngresos[MONTO],tblIngresos[FECHA],">="&$A10,tblIngresos[FECHA],"<"&EDATE($A10,1),tblIngresos[ESTADO],"PAGADO") -> 0 | G10: =D10-E10+F10 -> #REF!
A11: =EOMONTH(TODAY(),-7)+1 -> 45839 | B11: =SUMIFS(#REF!,#REF!,">="&$A11,#REF!,"<"&EDATE($A11,1),#REF!,"PAGADO") -> #REF! | C11: =SUMIFS(#REF!,#REF!,">="&$A11,#REF!,"<"&EDATE($A11,1),#REF!,"PAGADO") -> #REF! | D11: =B11-C11 -> #REF! | E11: =SUMIFS(tblGastos[MONTO],tblGastos[FECHA],">="&$A11,tblGastos[FECHA],"<"&EDATE($A11,1),tblGastos[ESTADO],"PAGADO") -> 0 | F11: =SUMIFS(tblIngresos[MONTO],tblIngresos[FECHA],">="&$A11,tblIngresos[FECHA],"<"&EDATE($A11,1),tblIngresos[ESTADO],"PAGADO") -> 0 | G11: =D11-E11+F11 -> #REF!
A12: =EOMONTH(TODAY(),-6)+1 -> 45870 | B12: =SUMIFS(#REF!,#REF!,">="&$A12,#REF!,"<"&EDATE($A12,1),#REF!,"PAGADO") -> #REF! | C12: =SUMIFS(#REF!,#REF!,">="&$A12,#REF!,"<"&EDATE($A12,1),#REF!,"PAGADO") -> #REF! | D12: =B12-C12 -> #REF! | E12: =SUMIFS(tblGastos[MONTO],tblGastos[FECHA],">="&$A12,tblGastos[FECHA],"<"&EDATE($A12,1),tblGastos[ESTADO],"PAGADO") -> 0 | F12: =SUMIFS(tblIngresos[MONTO],tblIngresos[FECHA],">="&$A12,tblIngresos[FECHA],"<"&EDATE($A12,1),tblIngresos[ESTADO],"PAGADO") -> 0 | G12: =D12-E12+F12 -> #REF!
A13: =EOMONTH(TODAY(),-5)+1 -> 45901 | B13: =SUMIFS(#REF!,#REF!,">="&$A13,#REF!,"<"&EDATE($A13,1),#REF!,"PAGADO") -> #REF! | C13: =SUMIFS(#REF!,#REF!,">="&$A13,#REF!,"<"&EDATE($A13,1),#REF!,"PAGADO") -> #REF! | D13: =B13-C13 -> #REF! | E13: =SUMIFS(tblGastos[MONTO],tblGastos[FECHA],">="&$A13,tblGastos[FECHA],"<"&EDATE($A13,1),tblGastos[ESTADO],"PAGADO") -> 0 | F13: =SUMIFS(tblIngresos[MONTO],tblIngresos[FECHA],">="&$A13,tblIngresos[FECHA],"<"&EDATE($A13,1),tblIngresos[ESTADO],"PAGADO") -> 0 | G13: =D13-E13+F13 -> #REF!
A14: =EOMONTH(TODAY(),-4)+1 -> 45931 | B14: =SUMIFS(#REF!,#REF!,">="&$A14,#REF!,"<"&EDATE($A14,1),#REF!,"PAGADO") -> #REF! | C14: =SUMIFS(#REF!,#REF!,">="&$A14,#REF!,"<"&EDATE($A14,1),#REF!,"PAGADO") -> #REF! | D14: =B14-C14 -> #REF! | E14: =SUMIFS(tblGastos[MONTO],tblGastos[FECHA],">="&$A14,tblGastos[FECHA],"<"&EDATE($A14,1),tblGastos[ESTADO],"PAGADO") -> 0 | F14: =SUMIFS(tblIngresos[MONTO],tblIngresos[FECHA],">="&$A14,tblIngresos[FECHA],"<"&EDATE($A14,1),tblIngresos[ESTADO],"PAGADO") -> 0 | G14: =D14-E14+F14 -> #REF!
A15: =EOMONTH(TODAY(),-3)+1 -> 45962 | B15: =SUMIFS(#REF!,#REF!,">="&$A15,#REF!,"<"&EDATE($A15,1),#REF!,"PAGADO") -> #REF! | C15: =SUMIFS(#REF!,#REF!,">="&$A15,#REF!,"<"&EDATE($A15,1),#REF!,"PAGADO") -> #REF! | D15: =B15-C15 -> #REF! | E15: =SUMIFS(tblGastos[MONTO],tblGastos[FECHA],">="&$A15,tblGastos[FECHA],"<"&EDATE($A15,1),tblGastos[ESTADO],"PAGADO") -> 0 | F15: =SUMIFS(tblIngresos[MONTO],tblIngresos[FECHA],">="&$A15,tblIngresos[FECHA],"<"&EDATE($A15,1),tblIngresos[ESTADO],"PAGADO") -> 0 | G15: =D15-E15+F15 -> #REF!
A16: =EOMONTH(TODAY(),-2)+1 -> 45992 | B16: =SUMIFS(#REF!,#REF!,">="&$A16,#REF!,"<"&EDATE($A16,1),#REF!,"PAGADO") -> #REF! | C16: =SUMIFS(#REF!,#REF!,">="&$A16,#REF!,"<"&EDATE($A16,1),#REF!,"PAGADO") -> #REF! | D16: =B16-C16 -> #REF! | E16: =SUMIFS(tblGastos[MONTO],tblGastos[FECHA],">="&$A16,tblGastos[FECHA],"<"&EDATE($A16,1),tblGastos[ESTADO],"PAGADO") -> 68307.76 | F16: =SUMIFS(tblIngresos[MONTO],tblIngresos[FECHA],">="&$A16,tblIngresos[FECHA],"<"&EDATE($A16,1),tblIngresos[ESTADO],"PAGADO") -> 0 | G16: =D16-E16+F16 -> #REF!
A17: =EOMONTH(TODAY(),-1)+1 -> 46023 | B17: =SUMIFS(#REF!,#REF!,">="&$A17,#REF!,"<"&EDATE($A17,1),#REF!,"PAGADO") -> #REF! | C17: =SUMIFS(#REF!,#REF!,">="&$A17,#REF!,"<"&EDATE($A17,1),#REF!,"PAGADO") -> #REF! | D17: =B17-C17 -> #REF! | E17: =SUMIFS(tblGastos[MONTO],tblGastos[FECHA],">="&$A17,tblGastos[FECHA],"<"&EDATE($A17,1),tblGastos[ESTADO],"PAGADO") -> 0 | F17: =SUMIFS(tblIngresos[MONTO],tblIngresos[FECHA],">="&$A17,tblIngresos[FECHA],"<"&EDATE($A17,1),tblIngresos[ESTADO],"PAGADO") -> 0 | G17: =D17-E17+F17 -> #REF!
A18: =EOMONTH(TODAY(),0)+1 -> 46054 | B18: =SUMIFS(#REF!,#REF!,">="&$A18,#REF!,"<"&EDATE($A18,1),#REF!,"PAGADO") -> #REF! | C18: =SUMIFS(#REF!,#REF!,">="&$A18,#REF!,"<"&EDATE($A18,1),#REF!,"PAGADO") -> #REF! | D18: =B18-C18 -> #REF! | E18: =SUMIFS(tblGastos[MONTO],tblGastos[FECHA],">="&$A18,tblGastos[FECHA],"<"&EDATE($A18,1),tblGastos[ESTADO],"PAGADO") -> 0 | F18: =SUMIFS(tblIngresos[MONTO],tblIngresos[FECHA],">="&$A18,tblIngresos[FECHA],"<"&EDATE($A18,1),tblIngresos[ESTADO],"PAGADO") -> 0 | G18: =D18-E18+F18 -> #REF!
A20: VENTAS POR CATEGORIA (12M) | D20: GASTOS POR CATEGORIA (12M)
A21: CATEGORIA | B21: VENTAS | D21: CATEGORIA | E21: GASTOS
A22: BALANCEADOS | B22: =SUMIFS(#REF!,#REF!,$A22,#REF!,">="&$H$7,#REF!,"<"&$H$8,#REF!,"PAGADO") -> #REF! | D22: ALQUILER | E22: =SUMIFS(tblGastos[MONTO],tblGastos[CATEGORIA_GASTO],$D22,tblGastos[FECHA],">="&$H$7,tblGastos[FECHA],"<"&$H$8,tblGastos[ESTADO],"PAGADO") -> 0
A23: DIETETIC | B23: =SUMIFS(#REF!,#REF!,$A23,#REF!,">="&$H$7,#REF!,"<"&$H$8,#REF!,"PAGADO") -> #REF! | D23: SERVICIOS | E23: =SUMIFS(tblGastos[MONTO],tblGastos[CATEGORIA_GASTO],$D23,tblGastos[FECHA],">="&$H$7,tblGastos[FECHA],"<"&$H$8,tblGastos[ESTADO],"PAGADO") -> 0
A24: SAPHIRUS AEROSOL | B24: =SUMIFS(#REF!,#REF!,$A24,#REF!,">="&$H$7,#REF!,"<"&$H$8,#REF!,"PAGADO") -> #REF! | D24: SUELDOS | E24: =SUMIFS(tblGastos[MONTO],tblGastos[CATEGORIA_GASTO],$D24,tblGastos[FECHA],">="&$H$7,tblGastos[FECHA],"<"&$H$8,tblGastos[ESTADO],"PAGADO") -> 0
A25: SAPHIRUS TEXTIL | B25: =SUMIFS(#REF!,#REF!,$A25,#REF!,">="&$H$7,#REF!,"<"&$H$8,#REF!,"PAGADO") -> #REF! | D25: PROVEEDORES | E25: =SUMIFS(tblGastos[MONTO],tblGastos[CATEGORIA_GASTO],$D25,tblGastos[FECHA],">="&$H$7,tblGastos[FECHA],"<"&$H$8,tblGastos[ESTADO],"PAGADO") -> 0
A26: SAPHIRUS VARILLAS | B26: =SUMIFS(#REF!,#REF!,$A26,#REF!,">="&$H$7,#REF!,"<"&$H$8,#REF!,"PAGADO") -> #REF! | D26: IMPUESTOS | E26: =SUMIFS(tblGastos[MONTO],tblGastos[CATEGORIA_GASTO],$D26,tblGastos[FECHA],">="&$H$7,tblGastos[FECHA],"<"&$H$8,tblGastos[ESTADO],"PAGADO") -> 0
A27: SATYA | B27: =SUMIFS(#REF!,#REF!,$A27,#REF!,">="&$H$7,#REF!,"<"&$H$8,#REF!,"PAGADO") -> #REF! | D27: MARKETING | E27: =SUMIFS(tblGastos[MONTO],tblGastos[CATEGORIA_GASTO],$D27,tblGastos[FECHA],">="&$H$7,tblGastos[FECHA],"<"&$H$8,tblGastos[ESTADO],"PAGADO") -> 0
D28: TRANSPORTE | E28: =SUMIFS(tblGastos[MONTO],tblGastos[CATEGORIA_GASTO],$D28,tblGastos[FECHA],">="&$H$7,tblGastos[FECHA],"<"&$H$8,tblGastos[ESTADO],"PAGADO") -> 0
D29: MANTENIMIENTO | E29: =SUMIFS(tblGastos[MONTO],tblGastos[CATEGORIA_GASTO],$D29,tblGastos[FECHA],">="&$H$7,tblGastos[FECHA],"<"&$H$8,tblGastos[ESTADO],"PAGADO") -> 0
D30: OTROS | E30: =SUMIFS(tblGastos[MONTO],tblGastos[CATEGORIA_GASTO],$D30,tblGastos[FECHA],">="&$H$7,tblGastos[FECHA],"<"&$H$8,tblGastos[ESTADO],"PAGADO") -> 0

Sheet Listas
A1: CATEGORIAS | C1: METODOS_PAGO | E1: CUENTAS | G1: CATEGORIAS_GASTO | I1: CATEGORIAS_INGRESO | K1: ESTADO | M1: PROVEEDORES
A2: BALANCEADOS | C2: EFECTIVO | E2: CAJA | G2: SEGURO | I2: VENTAS | K2: PAGADO | M2: VARIOS
A3: DIETETIC | C3: TRANSFERENCIA | E3: BBVA | G3: SERVICIOS | I3: SERVICIOS | K3: PENDIENTE | M3: SANCOR
A4: SAPHIRUS AEROSOL | C4: TARJETA | E4: MERCADOPAGO | G4: SUELDOS | I4: OTROS | K4: ANULADO
A5: SAPHIRUS TEXTIL | C5: MERCADOPAGO | G5: PROVEEDORES
A6: SAPHIRUS VARILLAS | C6: OTRO | G6: IMPUESTOS
A7: SATYA | G7: MARKETING
G8: TRANSPORTE
G9: MANTENIMIENTO
G10: OTROS

Sheet Ventas_old
A1: FECHA | B1: N° CLIENTE | C1: NOMBRE | D1: CATEGORIA | E1: PRODUCTO | F1: CANTIDAD | G1: PRECIO | H1: COSTO | I1: GANANCIAS
A2: 46022 | B2: =Clientes!A2 -> C001 | C2: Adri Puig | D2: Balanceados | E2: Voraz 20 KG | F2: 1 | G2: 22580 | H2: 17600 | I2: =G2-H2 -> 4980
A3: 46022 | B3: c007 | C3: Laura Pot | D3: Dietetic | E3: Avena instantanea | F3: 3 | G3: 3330 | H3: 1800 | I3: =G3-H3 -> 1530
A4: 46022 | B4: c009 | C4: Ari | D4: Saphirus Aerosol | E4: Coco Vai | F4: 1 | G4: 7200 | H4: 4894 | I4: =G4-H4 -> 2306

Sheet Categorias
A1: CATEGORIAS
A2: BALANCEADOS
A3: SAPHIRUS VARILLAS
A4: SAPHIRUS AEROSOL
A5: SAPHIRUS TEXTIL
